WARNING 2025-09-01 22:02:36,878 log 19908 7608 Not Found: /favicon.ico
WARNING 2025-09-01 22:02:36,879 basehttp 19908 7608 "GET /favicon.ico HTTP/1.1" 404 8728
ERROR 2025-09-01 22:03:03,290 log 19908 7608 Internal Server Error: /user/login/
Traceback (most recent call last):
  File "D:\Project\Tests\tests\Module 31_4\venv\Lib\site-packages\django\core\handlers\exception.py", line 55, in inner
    response = get_response(request)
  File "D:\Project\Tests\tests\Module 31_4\venv\Lib\site-packages\django\core\handlers\base.py", line 220, in _get_response
    response = response.render()
  File "D:\Project\Tests\tests\Module 31_4\venv\Lib\site-packages\django\template\response.py", line 114, in render
    self.content = self.rendered_content
                   ^^^^^^^^^^^^^^^^^^^^^
  File "D:\Project\Tests\tests\Module 31_4\venv\Lib\site-packages\django\template\response.py", line 90, in rendered_content
    template = self.resolve_template(self.template_name)
  File "D:\Project\Tests\tests\Module 31_4\venv\Lib\site-packages\django\template\response.py", line 72, in resolve_template
    return select_template(template, using=self.using)
  File "D:\Project\Tests\tests\Module 31_4\venv\Lib\site-packages\django\template\loader.py", line 47, in select_template
    raise TemplateDoesNotExist(", ".join(template_name_list), chain=chain)
django.template.exceptions.TemplateDoesNotExist: appUser/login.html
ERROR 2025-09-01 22:03:03,293 basehttp 19908 7608 "GET /user/login/ HTTP/1.1" 500 91605
ERROR 2025-09-01 22:03:08,556 log 19908 7608 Internal Server Error: /user/register/
Traceback (most recent call last):
  File "D:\Project\Tests\tests\Module 31_4\venv\Lib\site-packages\django\core\handlers\exception.py", line 55, in inner
    response = get_response(request)
  File "D:\Project\Tests\tests\Module 31_4\venv\Lib\site-packages\django\core\handlers\base.py", line 197, in _get_response
    response = wrapped_callback(request, *callback_args, **callback_kwargs)
  File "D:\Project\Tests\tests\Module 31_4\venv\Lib\site-packages\django\views\generic\base.py", line 105, in view
    return self.dispatch(request, *args, **kwargs)
           ~~~~~~~~~~~~~^^^^^^^^^^^^^^^^^^^^^^^^^^
  File "D:\Project\Tests\tests\Module 31_4\venv\Lib\site-packages\django\views\generic\base.py", line 144, in dispatch
    return handler(request, *args, **kwargs)
  File "D:\Project\Tests\tests\Module 31_4\appUser\views.py", line 22, in get
    return render(request, self.template_name, {'form': form})
  File "D:\Project\Tests\tests\Module 31_4\venv\Lib\site-packages\django\shortcuts.py", line 25, in render
    content = loader.render_to_string(template_name, context, request, using=using)
  File "D:\Project\Tests\tests\Module 31_4\venv\Lib\site-packages\django\template\loader.py", line 61, in render_to_string
    template = get_template(template_name, using=using)
  File "D:\Project\Tests\tests\Module 31_4\venv\Lib\site-packages\django\template\loader.py", line 19, in get_template
    raise TemplateDoesNotExist(template_name, chain=chain)
django.template.exceptions.TemplateDoesNotExist: appUser/register.html
ERROR 2025-09-01 22:03:08,562 basehttp 19908 7608 "GET /user/register/ HTTP/1.1" 500 102260
WARNING 2025-09-02 22:05:14,086 log 1800 17076 Not Found: /favicon.ico
WARNING 2025-09-02 22:05:14,086 basehttp 1800 17076 "GET /favicon.ico HTTP/1.1" 404 8728
WARNING 2025-09-02 22:14:19,069 log 12484 11392 Not Found: /favicon.ico
WARNING 2025-09-02 22:14:19,070 basehttp 12484 11392 "GET /favicon.ico HTTP/1.1" 404 8728
WARNING 2025-09-02 22:25:37,826 log 12484 13628 Method Not Allowed (GET): /user/logout/
WARNING 2025-09-02 22:25:37,834 basehttp 12484 13628 "GET /user/logout/ HTTP/1.1" 405 0
WARNING 2025-09-02 22:25:46,274 log 12484 18460 Method Not Allowed (GET): /user/logout/
WARNING 2025-09-02 22:25:46,284 basehttp 12484 18460 "GET /user/logout/ HTTP/1.1" 405 0
WARNING 2025-09-02 22:43:36,482 log 16644 3044 Method Not Allowed (GET): /user/logout/
WARNING 2025-09-02 22:43:36,494 basehttp 16644 3044 "GET /user/logout/ HTTP/1.1" 405 0
WARNING 2025-09-03 19:26:30,817 log 500 21424 Not Found: /favicon.ico
WARNING 2025-09-03 19:26:30,818 basehttp 500 21424 "GET /favicon.ico HTTP/1.1" 404 8728
ERROR 2025-09-03 19:30:43,413 log 500 21424 Internal Server Error: /posts/1/respond/
Traceback (most recent call last):
  File "D:\Project\Tests\tests\Module 31_4\venv\Lib\site-packages\django\core\handlers\exception.py", line 55, in inner
    response = get_response(request)
  File "D:\Project\Tests\tests\Module 31_4\venv\Lib\site-packages\django\core\handlers\base.py", line 220, in _get_response
    response = response.render()
  File "D:\Project\Tests\tests\Module 31_4\venv\Lib\site-packages\django\template\response.py", line 114, in render
    self.content = self.rendered_content
                   ^^^^^^^^^^^^^^^^^^^^^
  File "D:\Project\Tests\tests\Module 31_4\venv\Lib\site-packages\django\template\response.py", line 92, in rendered_content
    return template.render(context, self._request)
           ~~~~~~~~~~~~~~~^^^^^^^^^^^^^^^^^^^^^^^^
  File "D:\Project\Tests\tests\Module 31_4\venv\Lib\site-packages\django\template\backends\django.py", line 107, in render
    return self.template.render(context)
           ~~~~~~~~~~~~~~~~~~~~^^^^^^^^^
  File "D:\Project\Tests\tests\Module 31_4\venv\Lib\site-packages\django\template\base.py", line 171, in render
    return self._render(context)
           ~~~~~~~~~~~~^^^^^^^^^
  File "D:\Project\Tests\tests\Module 31_4\venv\Lib\site-packages\django\test\utils.py", line 114, in instrumented_test_render
    return self.nodelist.render(context)
           ~~~~~~~~~~~~~~~~~~~~^^^^^^^^^
  File "D:\Project\Tests\tests\Module 31_4\venv\Lib\site-packages\django\template\base.py", line 1016, in render
    return SafeString("".join([node.render_annotated(context) for node in self]))
                               ~~~~~~~~~~~~~~~~~~~~~^^^^^^^^^
  File "D:\Project\Tests\tests\Module 31_4\venv\Lib\site-packages\django\template\base.py", line 977, in render_annotated
    return self.render(context)
           ~~~~~~~~~~~^^^^^^^^^
  File "D:\Project\Tests\tests\Module 31_4\venv\Lib\site-packages\django\template\loader_tags.py", line 159, in render
    return compiled_parent._render(context)
           ~~~~~~~~~~~~~~~~~~~~~~~^^^^^^^^^
  File "D:\Project\Tests\tests\Module 31_4\venv\Lib\site-packages\django\test\utils.py", line 114, in instrumented_test_render
    return self.nodelist.render(context)
           ~~~~~~~~~~~~~~~~~~~~^^^^^^^^^
  File "D:\Project\Tests\tests\Module 31_4\venv\Lib\site-packages\django\template\base.py", line 1016, in render
    return SafeString("".join([node.render_annotated(context) for node in self]))
                               ~~~~~~~~~~~~~~~~~~~~~^^^^^^^^^
  File "D:\Project\Tests\tests\Module 31_4\venv\Lib\site-packages\django\template\base.py", line 977, in render_annotated
    return self.render(context)
           ~~~~~~~~~~~^^^^^^^^^
  File "D:\Project\Tests\tests\Module 31_4\venv\Lib\site-packages\django\template\loader_tags.py", line 65, in render
    result = block.nodelist.render(context)
  File "D:\Project\Tests\tests\Module 31_4\venv\Lib\site-packages\django\template\base.py", line 1016, in render
    return SafeString("".join([node.render_annotated(context) for node in self]))
                               ~~~~~~~~~~~~~~~~~~~~~^^^^^^^^^
  File "D:\Project\Tests\tests\Module 31_4\venv\Lib\site-packages\django\template\base.py", line 977, in render_annotated
    return self.render(context)
           ~~~~~~~~~~~^^^^^^^^^
  File "D:\Project\Tests\tests\Module 31_4\venv\Lib\site-packages\django\template\defaulttags.py", line 480, in render
    url = reverse(view_name, args=args, kwargs=kwargs, current_app=current_app)
  File "D:\Project\Tests\tests\Module 31_4\venv\Lib\site-packages\django\urls\base.py", line 98, in reverse
    resolved_url = resolver._reverse_with_prefix(view, prefix, *args, **kwargs)
  File "D:\Project\Tests\tests\Module 31_4\venv\Lib\site-packages\django\urls\resolvers.py", line 831, in _reverse_with_prefix
    raise NoReverseMatch(msg)
django.urls.exceptions.NoReverseMatch: Reverse for 'post_detail' with arguments '('',)' not found. 1 pattern(s) tried: ['posts/(?P<pk>[0-9]+)/\\Z']
ERROR 2025-09-03 19:30:43,435 basehttp 500 21424 "POST /posts/1/respond/ HTTP/1.1" 500 161443
WARNING 2025-09-03 20:01:29,473 log 22892 11828 Not Found: /favicon.ico
WARNING 2025-09-03 20:01:29,474 basehttp 22892 11828 "GET /favicon.ico HTTP/1.1" 404 8728
ERROR 2025-09-03 20:45:56,238 log 5188 18700 Internal Server Error: /cabinet/
Traceback (most recent call last):
  File "D:\Project\Tests\tests\Module 31_4\venv\Lib\site-packages\django\db\backends\utils.py", line 105, in _execute
    return self.cursor.execute(sql, params)
           ~~~~~~~~~~~~~~~~~~~^^^^^^^^^^^^^
  File "D:\Project\Tests\tests\Module 31_4\venv\Lib\site-packages\django\db\backends\sqlite3\base.py", line 360, in execute
    return super().execute(query, params)
           ~~~~~~~~~~~~~~~^^^^^^^^^^^^^^^
sqlite3.OperationalError: no such column: appNotification_response.is_rejected

The above exception was the direct cause of the following exception:

Traceback (most recent call last):
  File "D:\Project\Tests\tests\Module 31_4\venv\Lib\site-packages\django\core\handlers\exception.py", line 55, in inner
    response = get_response(request)
  File "D:\Project\Tests\tests\Module 31_4\venv\Lib\site-packages\django\core\handlers\base.py", line 197, in _get_response
    response = wrapped_callback(request, *callback_args, **callback_kwargs)
  File "D:\Project\Tests\tests\Module 31_4\venv\Lib\site-packages\django\contrib\auth\decorators.py", line 59, in _view_wrapper
    return view_func(request, *args, **kwargs)
  File "D:\Project\Tests\tests\Module 31_4\appNotification\views.py", line 266, in personal_cabinet
    return render_personal_cabinet(request)
  File "D:\Project\Tests\tests\Module 31_4\appNotification\views.py", line 372, in render_personal_cabinet
    return render(request, 'appNotification/lk.html', context)
  File "D:\Project\Tests\tests\Module 31_4\venv\Lib\site-packages\django\shortcuts.py", line 25, in render
    content = loader.render_to_string(template_name, context, request, using=using)
  File "D:\Project\Tests\tests\Module 31_4\venv\Lib\site-packages\django\template\loader.py", line 62, in render_to_string
    return template.render(context, request)
           ~~~~~~~~~~~~~~~^^^^^^^^^^^^^^^^^^
  File "D:\Project\Tests\tests\Module 31_4\venv\Lib\site-packages\django\template\backends\django.py", line 107, in render
    return self.template.render(context)
           ~~~~~~~~~~~~~~~~~~~~^^^^^^^^^
  File "D:\Project\Tests\tests\Module 31_4\venv\Lib\site-packages\django\template\base.py", line 171, in render
    return self._render(context)
           ~~~~~~~~~~~~^^^^^^^^^
  File "D:\Project\Tests\tests\Module 31_4\venv\Lib\site-packages\django\test\utils.py", line 114, in instrumented_test_render
    return self.nodelist.render(context)
           ~~~~~~~~~~~~~~~~~~~~^^^^^^^^^
  File "D:\Project\Tests\tests\Module 31_4\venv\Lib\site-packages\django\template\base.py", line 1016, in render
    return SafeString("".join([node.render_annotated(context) for node in self]))
                               ~~~~~~~~~~~~~~~~~~~~~^^^^^^^^^
  File "D:\Project\Tests\tests\Module 31_4\venv\Lib\site-packages\django\template\base.py", line 977, in render_annotated
    return self.render(context)
           ~~~~~~~~~~~^^^^^^^^^
  File "D:\Project\Tests\tests\Module 31_4\venv\Lib\site-packages\django\template\loader_tags.py", line 159, in render
    return compiled_parent._render(context)
           ~~~~~~~~~~~~~~~~~~~~~~~^^^^^^^^^
  File "D:\Project\Tests\tests\Module 31_4\venv\Lib\site-packages\django\test\utils.py", line 114, in instrumented_test_render
    return self.nodelist.render(context)
           ~~~~~~~~~~~~~~~~~~~~^^^^^^^^^
  File "D:\Project\Tests\tests\Module 31_4\venv\Lib\site-packages\django\template\base.py", line 1016, in render
    return SafeString("".join([node.render_annotated(context) for node in self]))
                               ~~~~~~~~~~~~~~~~~~~~~^^^^^^^^^
  File "D:\Project\Tests\tests\Module 31_4\venv\Lib\site-packages\django\template\base.py", line 977, in render_annotated
    return self.render(context)
           ~~~~~~~~~~~^^^^^^^^^
  File "D:\Project\Tests\tests\Module 31_4\venv\Lib\site-packages\django\template\loader_tags.py", line 65, in render
    result = block.nodelist.render(context)
  File "D:\Project\Tests\tests\Module 31_4\venv\Lib\site-packages\django\template\base.py", line 1016, in render
    return SafeString("".join([node.render_annotated(context) for node in self]))
                               ~~~~~~~~~~~~~~~~~~~~~^^^^^^^^^
  File "D:\Project\Tests\tests\Module 31_4\venv\Lib\site-packages\django\template\base.py", line 977, in render_annotated
    return self.render(context)
           ~~~~~~~~~~~^^^^^^^^^
  File "D:\Project\Tests\tests\Module 31_4\venv\Lib\site-packages\django\template\defaulttags.py", line 199, in render
    len_values = len(values)
  File "D:\Project\Tests\tests\Module 31_4\venv\Lib\site-packages\django\db\models\query.py", line 366, in __len__
    self._fetch_all()
    ~~~~~~~~~~~~~~~^^
  File "D:\Project\Tests\tests\Module 31_4\venv\Lib\site-packages\django\db\models\query.py", line 1949, in _fetch_all
    self._result_cache = list(self._iterable_class(self))
                         ~~~~^^^^^^^^^^^^^^^^^^^^^^^^^^^^
  File "D:\Project\Tests\tests\Module 31_4\venv\Lib\site-packages\django\db\models\query.py", line 91, in __iter__
    results = compiler.execute_sql(
        chunked_fetch=self.chunked_fetch, chunk_size=self.chunk_size
    )
  File "D:\Project\Tests\tests\Module 31_4\venv\Lib\site-packages\django\db\models\sql\compiler.py", line 1623, in execute_sql
    cursor.execute(sql, params)
    ~~~~~~~~~~~~~~^^^^^^^^^^^^^
  File "D:\Project\Tests\tests\Module 31_4\venv\Lib\site-packages\django\db\backends\utils.py", line 122, in execute
    return super().execute(sql, params)
           ~~~~~~~~~~~~~~~^^^^^^^^^^^^^
  File "D:\Project\Tests\tests\Module 31_4\venv\Lib\site-packages\django\db\backends\utils.py", line 79, in execute
    return self._execute_with_wrappers(
           ~~~~~~~~~~~~~~~~~~~~~~~~~~~^
        sql, params, many=False, executor=self._execute
        ^^^^^^^^^^^^^^^^^^^^^^^^^^^^^^^^^^^^^^^^^^^^^^^
    )
    ^
  File "D:\Project\Tests\tests\Module 31_4\venv\Lib\site-packages\django\db\backends\utils.py", line 92, in _execute_with_wrappers
    return executor(sql, params, many, context)
  File "D:\Project\Tests\tests\Module 31_4\venv\Lib\site-packages\django\db\backends\utils.py", line 100, in _execute
    with self.db.wrap_database_errors:
         ^^^^^^^^^^^^^^^^^^^^^^^^^^^^
  File "D:\Project\Tests\tests\Module 31_4\venv\Lib\site-packages\django\db\utils.py", line 91, in __exit__
    raise dj_exc_value.with_traceback(traceback) from exc_value
  File "D:\Project\Tests\tests\Module 31_4\venv\Lib\site-packages\django\db\backends\utils.py", line 105, in _execute
    return self.cursor.execute(sql, params)
           ~~~~~~~~~~~~~~~~~~~^^^^^^^^^^^^^
  File "D:\Project\Tests\tests\Module 31_4\venv\Lib\site-packages\django\db\backends\sqlite3\base.py", line 360, in execute
    return super().execute(query, params)
           ~~~~~~~~~~~~~~~^^^^^^^^^^^^^^^
django.db.utils.OperationalError: no such column: appNotification_response.is_rejected
ERROR 2025-09-03 20:45:56,247 basehttp 5188 18700 "GET /cabinet/ HTTP/1.1" 500 230302
ERROR 2025-09-03 20:46:28,343 log 5188 18700 Internal Server Error: /cabinet/
Traceback (most recent call last):
  File "D:\Project\Tests\tests\Module 31_4\venv\Lib\site-packages\django\db\backends\utils.py", line 105, in _execute
    return self.cursor.execute(sql, params)
           ~~~~~~~~~~~~~~~~~~~^^^^^^^^^^^^^
  File "D:\Project\Tests\tests\Module 31_4\venv\Lib\site-packages\django\db\backends\sqlite3\base.py", line 360, in execute
    return super().execute(query, params)
           ~~~~~~~~~~~~~~~^^^^^^^^^^^^^^^
sqlite3.OperationalError: no such column: appNotification_response.is_rejected

The above exception was the direct cause of the following exception:

Traceback (most recent call last):
  File "D:\Project\Tests\tests\Module 31_4\venv\Lib\site-packages\django\core\handlers\exception.py", line 55, in inner
    response = get_response(request)
  File "D:\Project\Tests\tests\Module 31_4\venv\Lib\site-packages\django\core\handlers\base.py", line 197, in _get_response
    response = wrapped_callback(request, *callback_args, **callback_kwargs)
  File "D:\Project\Tests\tests\Module 31_4\venv\Lib\site-packages\django\contrib\auth\decorators.py", line 59, in _view_wrapper
    return view_func(request, *args, **kwargs)
  File "D:\Project\Tests\tests\Module 31_4\appNotification\views.py", line 266, in personal_cabinet
    return render_personal_cabinet(request)
  File "D:\Project\Tests\tests\Module 31_4\appNotification\views.py", line 372, in render_personal_cabinet
    return render(request, 'appNotification/lk.html', context)
  File "D:\Project\Tests\tests\Module 31_4\venv\Lib\site-packages\django\shortcuts.py", line 25, in render
    content = loader.render_to_string(template_name, context, request, using=using)
  File "D:\Project\Tests\tests\Module 31_4\venv\Lib\site-packages\django\template\loader.py", line 62, in render_to_string
    return template.render(context, request)
           ~~~~~~~~~~~~~~~^^^^^^^^^^^^^^^^^^
  File "D:\Project\Tests\tests\Module 31_4\venv\Lib\site-packages\django\template\backends\django.py", line 107, in render
    return self.template.render(context)
           ~~~~~~~~~~~~~~~~~~~~^^^^^^^^^
  File "D:\Project\Tests\tests\Module 31_4\venv\Lib\site-packages\django\template\base.py", line 171, in render
    return self._render(context)
           ~~~~~~~~~~~~^^^^^^^^^
  File "D:\Project\Tests\tests\Module 31_4\venv\Lib\site-packages\django\test\utils.py", line 114, in instrumented_test_render
    return self.nodelist.render(context)
           ~~~~~~~~~~~~~~~~~~~~^^^^^^^^^
  File "D:\Project\Tests\tests\Module 31_4\venv\Lib\site-packages\django\template\base.py", line 1016, in render
    return SafeString("".join([node.render_annotated(context) for node in self]))
                               ~~~~~~~~~~~~~~~~~~~~~^^^^^^^^^
  File "D:\Project\Tests\tests\Module 31_4\venv\Lib\site-packages\django\template\base.py", line 977, in render_annotated
    return self.render(context)
           ~~~~~~~~~~~^^^^^^^^^
  File "D:\Project\Tests\tests\Module 31_4\venv\Lib\site-packages\django\template\loader_tags.py", line 159, in render
    return compiled_parent._render(context)
           ~~~~~~~~~~~~~~~~~~~~~~~^^^^^^^^^
  File "D:\Project\Tests\tests\Module 31_4\venv\Lib\site-packages\django\test\utils.py", line 114, in instrumented_test_render
    return self.nodelist.render(context)
           ~~~~~~~~~~~~~~~~~~~~^^^^^^^^^
  File "D:\Project\Tests\tests\Module 31_4\venv\Lib\site-packages\django\template\base.py", line 1016, in render
    return SafeString("".join([node.render_annotated(context) for node in self]))
                               ~~~~~~~~~~~~~~~~~~~~~^^^^^^^^^
  File "D:\Project\Tests\tests\Module 31_4\venv\Lib\site-packages\django\template\base.py", line 977, in render_annotated
    return self.render(context)
           ~~~~~~~~~~~^^^^^^^^^
  File "D:\Project\Tests\tests\Module 31_4\venv\Lib\site-packages\django\template\loader_tags.py", line 65, in render
    result = block.nodelist.render(context)
  File "D:\Project\Tests\tests\Module 31_4\venv\Lib\site-packages\django\template\base.py", line 1016, in render
    return SafeString("".join([node.render_annotated(context) for node in self]))
                               ~~~~~~~~~~~~~~~~~~~~~^^^^^^^^^
  File "D:\Project\Tests\tests\Module 31_4\venv\Lib\site-packages\django\template\base.py", line 977, in render_annotated
    return self.render(context)
           ~~~~~~~~~~~^^^^^^^^^
  File "D:\Project\Tests\tests\Module 31_4\venv\Lib\site-packages\django\template\defaulttags.py", line 199, in render
    len_values = len(values)
  File "D:\Project\Tests\tests\Module 31_4\venv\Lib\site-packages\django\db\models\query.py", line 366, in __len__
    self._fetch_all()
    ~~~~~~~~~~~~~~~^^
  File "D:\Project\Tests\tests\Module 31_4\venv\Lib\site-packages\django\db\models\query.py", line 1949, in _fetch_all
    self._result_cache = list(self._iterable_class(self))
                         ~~~~^^^^^^^^^^^^^^^^^^^^^^^^^^^^
  File "D:\Project\Tests\tests\Module 31_4\venv\Lib\site-packages\django\db\models\query.py", line 91, in __iter__
    results = compiler.execute_sql(
        chunked_fetch=self.chunked_fetch, chunk_size=self.chunk_size
    )
  File "D:\Project\Tests\tests\Module 31_4\venv\Lib\site-packages\django\db\models\sql\compiler.py", line 1623, in execute_sql
    cursor.execute(sql, params)
    ~~~~~~~~~~~~~~^^^^^^^^^^^^^
  File "D:\Project\Tests\tests\Module 31_4\venv\Lib\site-packages\django\db\backends\utils.py", line 122, in execute
    return super().execute(sql, params)
           ~~~~~~~~~~~~~~~^^^^^^^^^^^^^
  File "D:\Project\Tests\tests\Module 31_4\venv\Lib\site-packages\django\db\backends\utils.py", line 79, in execute
    return self._execute_with_wrappers(
           ~~~~~~~~~~~~~~~~~~~~~~~~~~~^
        sql, params, many=False, executor=self._execute
        ^^^^^^^^^^^^^^^^^^^^^^^^^^^^^^^^^^^^^^^^^^^^^^^
    )
    ^
  File "D:\Project\Tests\tests\Module 31_4\venv\Lib\site-packages\django\db\backends\utils.py", line 92, in _execute_with_wrappers
    return executor(sql, params, many, context)
  File "D:\Project\Tests\tests\Module 31_4\venv\Lib\site-packages\django\db\backends\utils.py", line 100, in _execute
    with self.db.wrap_database_errors:
         ^^^^^^^^^^^^^^^^^^^^^^^^^^^^
  File "D:\Project\Tests\tests\Module 31_4\venv\Lib\site-packages\django\db\utils.py", line 91, in __exit__
    raise dj_exc_value.with_traceback(traceback) from exc_value
  File "D:\Project\Tests\tests\Module 31_4\venv\Lib\site-packages\django\db\backends\utils.py", line 105, in _execute
    return self.cursor.execute(sql, params)
           ~~~~~~~~~~~~~~~~~~~^^^^^^^^^^^^^
  File "D:\Project\Tests\tests\Module 31_4\venv\Lib\site-packages\django\db\backends\sqlite3\base.py", line 360, in execute
    return super().execute(query, params)
           ~~~~~~~~~~~~~~~^^^^^^^^^^^^^^^
django.db.utils.OperationalError: no such column: appNotification_response.is_rejected
ERROR 2025-09-03 20:46:28,351 basehttp 5188 18700 "GET /cabinet/ HTTP/1.1" 500 230308
ERROR 2025-09-03 22:18:34,547 log 8564 3116 Internal Server Error: /
Traceback (most recent call last):
  File "D:\Project\Tests\tests\Module 31_4\venv\Lib\site-packages\django\core\handlers\exception.py", line 55, in inner
    response = get_response(request)
  File "D:\Project\Tests\tests\Module 31_4\venv\Lib\site-packages\django\core\handlers\base.py", line 185, in _get_response
    response = middleware_method(
        request, callback, callback_args, callback_kwargs
    )
  File "D:\Project\Tests\tests\Module 31_4\appUser\middleware.py", line 39, in process_view
    reverse('verify_email'),
    ~~~~~~~^^^^^^^^^^^^^^^^
  File "D:\Project\Tests\tests\Module 31_4\venv\Lib\site-packages\django\urls\base.py", line 98, in reverse
    resolved_url = resolver._reverse_with_prefix(view, prefix, *args, **kwargs)
  File "D:\Project\Tests\tests\Module 31_4\venv\Lib\site-packages\django\urls\resolvers.py", line 831, in _reverse_with_prefix
    raise NoReverseMatch(msg)
django.urls.exceptions.NoReverseMatch: Reverse for 'verify_email' with no arguments not found. 1 pattern(s) tried: ['user/verify/(?P<code>[^/]+)/\\Z']
ERROR 2025-09-03 22:18:34,551 basehttp 8564 3116 "GET / HTTP/1.1" 500 90069
ERROR 2025-09-03 22:33:07,710 log 7744 14892 Internal Server Error: /user/verify/1P_l05vT8rKqr-kHPI7fJinXvz7W6vZJUrJSHTb1hJI/
Traceback (most recent call last):
  File "D:\Project\Tests\tests\Module 31_4\venv\Lib\site-packages\django\core\handlers\exception.py", line 55, in inner
    response = get_response(request)
  File "D:\Project\Tests\tests\Module 31_4\venv\Lib\site-packages\django\core\handlers\base.py", line 185, in _get_response
    response = middleware_method(
        request, callback, callback_args, callback_kwargs
    )
  File "D:\Project\Tests\tests\Module 31_4\appUser\middleware.py", line 39, in process_view
    reverse('verify_email'),
    ~~~~~~~^^^^^^^^^^^^^^^^
  File "D:\Project\Tests\tests\Module 31_4\venv\Lib\site-packages\django\urls\base.py", line 98, in reverse
    resolved_url = resolver._reverse_with_prefix(view, prefix, *args, **kwargs)
  File "D:\Project\Tests\tests\Module 31_4\venv\Lib\site-packages\django\urls\resolvers.py", line 831, in _reverse_with_prefix
    raise NoReverseMatch(msg)
django.urls.exceptions.NoReverseMatch: Reverse for 'verify_email' with no arguments not found. 1 pattern(s) tried: ['user/verify/(?P<code>[^/]+)/\\Z']
ERROR 2025-09-03 22:33:07,712 basehttp 7744 14892 "GET /user/verify/1P_l05vT8rKqr-kHPI7fJinXvz7W6vZJUrJSHTb1hJI/ HTTP/1.1" 500 90432
WARNING 2025-09-04 19:39:29,993 log 22508 17428 Not Found: /favicon.ico
WARNING 2025-09-04 19:39:29,993 basehttp 22508 17428 "GET /favicon.ico HTTP/1.1" 404 9306
WARNING 2025-09-04 19:40:36,400 log 22508 20608 Not Found: /favicon.ico
WARNING 2025-09-04 19:40:36,400 basehttp 22508 20608 "GET /favicon.ico HTTP/1.1" 404 9306
